2024-07-23 08:17:32,308 INFO    StreamThr :208221 [internal.py:wandb_internal():86] W&B internal server running at pid: 208221, started at: 2024-07-23 08:17:32.306797
2024-07-23 08:17:32,319 DEBUG   HandlerThread:208221 [handler.py:handle_request():146] handle_request: status
2024-07-23 08:17:32,344 INFO    WriterThread:208221 [datastore.py:open_for_write():87] open: /home/somya/thesis/FEDGMM/sp_decentralized_mnist_lr_example/wandb/run-20240723_081732-i9zwonv0/run-i9zwonv0.wandb
2024-07-23 08:17:32,345 DEBUG   SenderThread:208221 [sender.py:send():382] send: header
2024-07-23 08:17:32,365 DEBUG   SenderThread:208221 [sender.py:send():382] send: run
2024-07-23 08:17:33,017 ERROR   SenderThread:208221 [internal_api.py:execute():373] 404 response executing GraphQL.
2024-07-23 08:17:33,018 ERROR   SenderThread:208221 [internal_api.py:execute():374] {"errors":[{"message":"project not found","path":["upsertBucket"]}],"data":{"upsertBucket":null}}
2024-07-23 08:17:33,019 ERROR   SenderThread:208221 [sender.py:send_run():987] It appears that you do not have permission to access the requested resource. Please reach out to the project owner to grant you access. If you have the correct permissions, verify that there are no issues with your networking setup.(Error 404: Not Found)
Traceback (most recent call last):
  File "/home/somya/miniconda3/envs/dl/lib/python3.11/site-packages/wandb/sdk/lib/retry.py", line 131, in __call__
    result = self._call_fn(*args, **kwargs)
             ^^^^^^^^^^^^^^^^^^^^^^^^^^^^^^
  File "/home/somya/miniconda3/envs/dl/lib/python3.11/site-packages/wandb/sdk/internal/internal_api.py", line 369, in execute
    return self.client.execute(*args, **kwargs)  # type: ignore
           ^^^^^^^^^^^^^^^^^^^^^^^^^^^^^^^^^^^^
  File "/home/somya/miniconda3/envs/dl/lib/python3.11/site-packages/wandb/vendor/gql-0.2.0/wandb_gql/client.py", line 52, in execute
    result = self._get_result(document, *args, **kwargs)
             ^^^^^^^^^^^^^^^^^^^^^^^^^^^^^^^^^^^^^^^^^^^
  File "/home/somya/miniconda3/envs/dl/lib/python3.11/site-packages/wandb/vendor/gql-0.2.0/wandb_gql/client.py", line 60, in _get_result
    return self.transport.execute(document, *args, **kwargs)
           ^^^^^^^^^^^^^^^^^^^^^^^^^^^^^^^^^^^^^^^^^^^^^^^^^
  File "/home/somya/miniconda3/envs/dl/lib/python3.11/site-packages/wandb/sdk/lib/gql_request.py", line 59, in execute
    request.raise_for_status()
  File "/home/somya/miniconda3/envs/dl/lib/python3.11/site-packages/requests/models.py", line 1021, in raise_for_status
    raise HTTPError(http_error_msg, response=self)
requests.exceptions.HTTPError: 404 Client Error: Not Found for url: https://api.wandb.ai/graphql

During handling of the above exception, another exception occurred:

Traceback (most recent call last):
  File "/home/somya/miniconda3/envs/dl/lib/python3.11/site-packages/wandb/sdk/internal/sender.py", line 985, in send_run
    self._init_run(run, config_value_dict)
  File "/home/somya/miniconda3/envs/dl/lib/python3.11/site-packages/wandb/sdk/internal/sender.py", line 1027, in _init_run
    server_run, inserted, server_messages = self._api.upsert_run(
                                            ^^^^^^^^^^^^^^^^^^^^^
  File "/home/somya/miniconda3/envs/dl/lib/python3.11/site-packages/wandb/apis/normalize.py", line 73, in wrapper
    raise err
  File "/home/somya/miniconda3/envs/dl/lib/python3.11/site-packages/wandb/apis/normalize.py", line 41, in wrapper
    return func(*args, **kwargs)
           ^^^^^^^^^^^^^^^^^^^^^
  File "/home/somya/miniconda3/envs/dl/lib/python3.11/site-packages/wandb/sdk/internal/internal_api.py", line 2216, in upsert_run
    response = self.gql(
               ^^^^^^^^^
  File "/home/somya/miniconda3/envs/dl/lib/python3.11/site-packages/wandb/sdk/internal/internal_api.py", line 341, in gql
    ret = self._retry_gql(
          ^^^^^^^^^^^^^^^^
  File "/home/somya/miniconda3/envs/dl/lib/python3.11/site-packages/wandb/sdk/lib/retry.py", line 147, in __call__
    retry_timedelta_triggered = check_retry_fn(e)
                                ^^^^^^^^^^^^^^^^^
  File "/home/somya/miniconda3/envs/dl/lib/python3.11/site-packages/wandb/util.py", line 965, in check_retry_fn
    return fallback_retry_fn(e)
           ^^^^^^^^^^^^^^^^^^^^
  File "/home/somya/miniconda3/envs/dl/lib/python3.11/site-packages/wandb/util.py", line 907, in no_retry_auth
    raise CommError(
wandb.errors.CommError: It appears that you do not have permission to access the requested resource. Please reach out to the project owner to grant you access. If you have the correct permissions, verify that there are no issues with your networking setup.(Error 404: Not Found)
2024-07-23 08:17:38,033 DEBUG   HandlerThread:208221 [handler.py:handle_request():146] handle_request: status_report
2024-07-23 08:17:43,034 DEBUG   HandlerThread:208221 [handler.py:handle_request():146] handle_request: status_report
2024-07-23 08:17:48,037 DEBUG   HandlerThread:208221 [handler.py:handle_request():146] handle_request: status_report
2024-07-23 08:17:53,037 DEBUG   HandlerThread:208221 [handler.py:handle_request():146] handle_request: status_report
2024-07-23 08:17:58,038 DEBUG   HandlerThread:208221 [handler.py:handle_request():146] handle_request: status_report
2024-07-23 08:18:03,040 DEBUG   HandlerThread:208221 [handler.py:handle_request():146] handle_request: status_report
2024-07-23 08:18:08,041 DEBUG   HandlerThread:208221 [handler.py:handle_request():146] handle_request: status_report
2024-07-23 08:18:13,044 DEBUG   HandlerThread:208221 [handler.py:handle_request():146] handle_request: status_report
2024-07-23 08:18:18,044 DEBUG   HandlerThread:208221 [handler.py:handle_request():146] handle_request: status_report
2024-07-23 08:18:23,045 DEBUG   HandlerThread:208221 [handler.py:handle_request():146] handle_request: status_report
2024-07-23 08:18:28,046 DEBUG   HandlerThread:208221 [handler.py:handle_request():146] handle_request: status_report
2024-07-23 08:18:33,048 DEBUG   HandlerThread:208221 [handler.py:handle_request():146] handle_request: status_report
2024-07-23 08:18:38,049 DEBUG   HandlerThread:208221 [handler.py:handle_request():146] handle_request: status_report
2024-07-23 08:18:43,050 DEBUG   HandlerThread:208221 [handler.py:handle_request():146] handle_request: status_report
2024-07-23 08:18:48,052 DEBUG   HandlerThread:208221 [handler.py:handle_request():146] handle_request: status_report
2024-07-23 08:18:53,053 DEBUG   HandlerThread:208221 [handler.py:handle_request():146] handle_request: status_report
2024-07-23 08:18:58,054 DEBUG   HandlerThread:208221 [handler.py:handle_request():146] handle_request: status_report
2024-07-23 08:19:03,054 DEBUG   HandlerThread:208221 [handler.py:handle_request():146] handle_request: status_report
2024-07-23 08:19:08,057 DEBUG   HandlerThread:208221 [handler.py:handle_request():146] handle_request: status_report
2024-07-23 08:19:13,058 DEBUG   HandlerThread:208221 [handler.py:handle_request():146] handle_request: status_report
2024-07-23 08:19:18,059 DEBUG   HandlerThread:208221 [handler.py:handle_request():146] handle_request: status_report
2024-07-23 08:19:23,060 DEBUG   HandlerThread:208221 [handler.py:handle_request():146] handle_request: status_report
2024-07-23 08:19:28,061 DEBUG   HandlerThread:208221 [handler.py:handle_request():146] handle_request: status_report
2024-07-23 08:19:33,062 DEBUG   HandlerThread:208221 [handler.py:handle_request():146] handle_request: status_report
2024-07-23 08:19:38,063 DEBUG   HandlerThread:208221 [handler.py:handle_request():146] handle_request: status_report
2024-07-23 08:19:43,064 DEBUG   HandlerThread:208221 [handler.py:handle_request():146] handle_request: status_report
