2024-07-25 00:55:18,424 INFO    StreamThr :444873 [internal.py:wandb_internal():90] W&B internal server running at pid: 444873, started at: 2024-07-25 00:55:18.422740
2024-07-25 00:55:18,433 DEBUG   HandlerThread:444873 [handler.py:handle_request():141] handle_request: status
2024-07-25 00:55:18,434 DEBUG   SenderThread:444873 [sender.py:send_request():316] send_request: status
2024-07-25 00:55:18,451 DEBUG   SenderThread:444873 [sender.py:send():302] send: header
2024-07-25 00:55:18,451 INFO    WriterThread:444873 [datastore.py:open_for_write():75] open: /home/somya/thesis/fedgmm/sp_decentralized_mnist_lr_example/wandb/run-20240725_005518-31qwx13f/run-31qwx13f.wandb
2024-07-25 00:55:18,475 DEBUG   SenderThread:444873 [sender.py:send():302] send: run
2024-07-25 00:55:19,140 ERROR   SenderThread:444873 [internal_api.py:execute():207] 403 response executing GraphQL.
2024-07-25 00:55:19,140 ERROR   SenderThread:444873 [internal_api.py:execute():208] {"errors":[{"message":"permission denied","path":["upsertBucket"],"extensions":{"code":"PERMISSION_ERROR"}}],"data":{"upsertBucket":null}}
2024-07-25 00:55:19,475 INFO    WriterThread:444873 [datastore.py:close():279] close: /home/somya/thesis/fedgmm/sp_decentralized_mnist_lr_example/wandb/run-20240725_005518-31qwx13f/run-31qwx13f.wandb
2024-07-25 00:55:19,476 INFO    HandlerThread:444873 [handler.py:finish():810] shutting down handler
2024-07-25 00:55:19,477 ERROR   StreamThr :444873 [internal.py:wandb_internal():165] Thread SenderThread:
Traceback (most recent call last):
  File "/home/somya/miniconda3/envs/dl/lib/python3.11/site-packages/wandb/sdk/lib/retry.py", line 113, in __call__
    result = self._call_fn(*args, **kwargs)
             ^^^^^^^^^^^^^^^^^^^^^^^^^^^^^^
  File "/home/somya/miniconda3/envs/dl/lib/python3.11/site-packages/wandb/sdk/internal/internal_api.py", line 204, in execute
    return self.client.execute(*args, **kwargs)  # type: ignore
           ^^^^^^^^^^^^^^^^^^^^^^^^^^^^^^^^^^^^
  File "/home/somya/miniconda3/envs/dl/lib/python3.11/site-packages/wandb/vendor/gql-0.2.0/wandb_gql/client.py", line 52, in execute
    result = self._get_result(document, *args, **kwargs)
             ^^^^^^^^^^^^^^^^^^^^^^^^^^^^^^^^^^^^^^^^^^^
  File "/home/somya/miniconda3/envs/dl/lib/python3.11/site-packages/wandb/vendor/gql-0.2.0/wandb_gql/client.py", line 60, in _get_result
    return self.transport.execute(document, *args, **kwargs)
           ^^^^^^^^^^^^^^^^^^^^^^^^^^^^^^^^^^^^^^^^^^^^^^^^^
  File "/home/somya/miniconda3/envs/dl/lib/python3.11/site-packages/wandb/vendor/gql-0.2.0/wandb_gql/transport/requests.py", line 39, in execute
    request.raise_for_status()
  File "/home/somya/miniconda3/envs/dl/lib/python3.11/site-packages/requests/models.py", line 1021, in raise_for_status
    raise HTTPError(http_error_msg, response=self)
requests.exceptions.HTTPError: 403 Client Error: Forbidden for url: https://api.wandb.ai/graphql

During handling of the above exception, another exception occurred:

Traceback (most recent call last):
  File "/home/somya/miniconda3/envs/dl/lib/python3.11/site-packages/wandb/apis/normalize.py", line 25, in wrapper
    return func(*args, **kwargs)
           ^^^^^^^^^^^^^^^^^^^^^
  File "/home/somya/miniconda3/envs/dl/lib/python3.11/site-packages/wandb/sdk/internal/internal_api.py", line 1465, in upsert_run
    response = self.gql(
               ^^^^^^^^^
  File "/home/somya/miniconda3/envs/dl/lib/python3.11/site-packages/wandb/sdk/lib/retry.py", line 129, in __call__
    retry_timedelta_triggered = check_retry_fn(e)
                                ^^^^^^^^^^^^^^^^^
  File "/home/somya/miniconda3/envs/dl/lib/python3.11/site-packages/wandb/util.py", line 942, in check_retry_fn
    return fallback_retry_fn(e)
           ^^^^^^^^^^^^^^^^^^^^
  File "/home/somya/miniconda3/envs/dl/lib/python3.11/site-packages/wandb/util.py", line 889, in no_retry_auth
    raise CommError("Permission denied, ask the project owner to grant you access")
wandb.errors.CommError: Permission denied, ask the project owner to grant you access

During handling of the above exception, another exception occurred:

Traceback (most recent call last):
  File "/home/somya/miniconda3/envs/dl/lib/python3.11/site-packages/wandb/sdk/internal/internal_util.py", line 51, in run
    self._run()
  File "/home/somya/miniconda3/envs/dl/lib/python3.11/site-packages/wandb/sdk/internal/internal_util.py", line 102, in _run
    self._process(record)
  File "/home/somya/miniconda3/envs/dl/lib/python3.11/site-packages/wandb/sdk/internal/internal.py", line 310, in _process
    self._sm.send(record)
  File "/home/somya/miniconda3/envs/dl/lib/python3.11/site-packages/wandb/sdk/internal/sender.py", line 304, in send
    send_handler(record)
  File "/home/somya/miniconda3/envs/dl/lib/python3.11/site-packages/wandb/sdk/internal/sender.py", line 782, in send_run
    self._init_run(run, config_value_dict)
  File "/home/somya/miniconda3/envs/dl/lib/python3.11/site-packages/wandb/sdk/internal/sender.py", line 808, in _init_run
    server_run, inserted, server_messages = self._api.upsert_run(
                                            ^^^^^^^^^^^^^^^^^^^^^
  File "/home/somya/miniconda3/envs/dl/lib/python3.11/site-packages/wandb/apis/normalize.py", line 61, in wrapper
    raise CommError(message, err).with_traceback(sys.exc_info()[2])
  File "/home/somya/miniconda3/envs/dl/lib/python3.11/site-packages/wandb/apis/normalize.py", line 25, in wrapper
    return func(*args, **kwargs)
           ^^^^^^^^^^^^^^^^^^^^^
  File "/home/somya/miniconda3/envs/dl/lib/python3.11/site-packages/wandb/sdk/internal/internal_api.py", line 1465, in upsert_run
    response = self.gql(
               ^^^^^^^^^
  File "/home/somya/miniconda3/envs/dl/lib/python3.11/site-packages/wandb/sdk/lib/retry.py", line 129, in __call__
    retry_timedelta_triggered = check_retry_fn(e)
                                ^^^^^^^^^^^^^^^^^
  File "/home/somya/miniconda3/envs/dl/lib/python3.11/site-packages/wandb/util.py", line 942, in check_retry_fn
    return fallback_retry_fn(e)
           ^^^^^^^^^^^^^^^^^^^^
  File "/home/somya/miniconda3/envs/dl/lib/python3.11/site-packages/wandb/util.py", line 889, in no_retry_auth
    raise CommError("Permission denied, ask the project owner to grant you access")
wandb.errors.CommError: Permission denied, ask the project owner to grant you access
