2024-07-24 05:39:37,465 INFO    StreamThr :367487 [internal.py:wandb_internal():86] W&B internal server running at pid: 367487, started at: 2024-07-24 05:39:37.463916
2024-07-24 05:39:37,470 DEBUG   HandlerThread:367487 [handler.py:handle_request():146] handle_request: status
2024-07-24 05:39:37,490 INFO    WriterThread:367487 [datastore.py:open_for_write():87] open: /home/somya/thesis/fedgmm/sp_decentralized_mnist_lr_example/wandb/run-20240724_053937-q2y3tlks/run-q2y3tlks.wandb
2024-07-24 05:39:37,492 DEBUG   SenderThread:367487 [sender.py:send():382] send: header
2024-07-24 05:39:37,507 DEBUG   SenderThread:367487 [sender.py:send():382] send: run
2024-07-24 05:39:38,202 ERROR   SenderThread:367487 [internal_api.py:execute():373] 403 response executing GraphQL.
2024-07-24 05:39:38,202 ERROR   SenderThread:367487 [internal_api.py:execute():374] {"errors":[{"message":"permission denied","path":["upsertBucket"],"extensions":{"code":"PERMISSION_ERROR"}}],"data":{"upsertBucket":null}}
2024-07-24 05:39:38,203 ERROR   SenderThread:367487 [sender.py:send_run():987] It appears that you do not have permission to access the requested resource. Please reach out to the project owner to grant you access. If you have the correct permissions, verify that there are no issues with your networking setup.(Error 403: Forbidden)
Traceback (most recent call last):
  File "/home/somya/miniconda3/envs/dl/lib/python3.11/site-packages/wandb/sdk/lib/retry.py", line 131, in __call__
    result = self._call_fn(*args, **kwargs)
             ^^^^^^^^^^^^^^^^^^^^^^^^^^^^^^
  File "/home/somya/miniconda3/envs/dl/lib/python3.11/site-packages/wandb/sdk/internal/internal_api.py", line 369, in execute
    return self.client.execute(*args, **kwargs)  # type: ignore
           ^^^^^^^^^^^^^^^^^^^^^^^^^^^^^^^^^^^^
  File "/home/somya/miniconda3/envs/dl/lib/python3.11/site-packages/wandb/vendor/gql-0.2.0/wandb_gql/client.py", line 52, in execute
    result = self._get_result(document, *args, **kwargs)
             ^^^^^^^^^^^^^^^^^^^^^^^^^^^^^^^^^^^^^^^^^^^
  File "/home/somya/miniconda3/envs/dl/lib/python3.11/site-packages/wandb/vendor/gql-0.2.0/wandb_gql/client.py", line 60, in _get_result
    return self.transport.execute(document, *args, **kwargs)
           ^^^^^^^^^^^^^^^^^^^^^^^^^^^^^^^^^^^^^^^^^^^^^^^^^
  File "/home/somya/miniconda3/envs/dl/lib/python3.11/site-packages/wandb/sdk/lib/gql_request.py", line 59, in execute
    request.raise_for_status()
  File "/home/somya/miniconda3/envs/dl/lib/python3.11/site-packages/requests/models.py", line 1021, in raise_for_status
    raise HTTPError(http_error_msg, response=self)
requests.exceptions.HTTPError: 403 Client Error: Forbidden for url: https://api.wandb.ai/graphql

During handling of the above exception, another exception occurred:

Traceback (most recent call last):
  File "/home/somya/miniconda3/envs/dl/lib/python3.11/site-packages/wandb/sdk/internal/sender.py", line 985, in send_run
    self._init_run(run, config_value_dict)
  File "/home/somya/miniconda3/envs/dl/lib/python3.11/site-packages/wandb/sdk/internal/sender.py", line 1027, in _init_run
    server_run, inserted, server_messages = self._api.upsert_run(
                                            ^^^^^^^^^^^^^^^^^^^^^
  File "/home/somya/miniconda3/envs/dl/lib/python3.11/site-packages/wandb/apis/normalize.py", line 73, in wrapper
    raise err
  File "/home/somya/miniconda3/envs/dl/lib/python3.11/site-packages/wandb/apis/normalize.py", line 41, in wrapper
    return func(*args, **kwargs)
           ^^^^^^^^^^^^^^^^^^^^^
  File "/home/somya/miniconda3/envs/dl/lib/python3.11/site-packages/wandb/sdk/internal/internal_api.py", line 2216, in upsert_run
    response = self.gql(
               ^^^^^^^^^
  File "/home/somya/miniconda3/envs/dl/lib/python3.11/site-packages/wandb/sdk/internal/internal_api.py", line 341, in gql
    ret = self._retry_gql(
          ^^^^^^^^^^^^^^^^
  File "/home/somya/miniconda3/envs/dl/lib/python3.11/site-packages/wandb/sdk/lib/retry.py", line 147, in __call__
    retry_timedelta_triggered = check_retry_fn(e)
                                ^^^^^^^^^^^^^^^^^
  File "/home/somya/miniconda3/envs/dl/lib/python3.11/site-packages/wandb/util.py", line 965, in check_retry_fn
    return fallback_retry_fn(e)
           ^^^^^^^^^^^^^^^^^^^^
  File "/home/somya/miniconda3/envs/dl/lib/python3.11/site-packages/wandb/util.py", line 907, in no_retry_auth
    raise CommError(
wandb.errors.CommError: It appears that you do not have permission to access the requested resource. Please reach out to the project owner to grant you access. If you have the correct permissions, verify that there are no issues with your networking setup.(Error 403: Forbidden)
2024-07-24 05:39:43,218 DEBUG   HandlerThread:367487 [handler.py:handle_request():146] handle_request: status_report
2024-07-24 05:39:48,219 DEBUG   HandlerThread:367487 [handler.py:handle_request():146] handle_request: status_report
2024-07-24 05:39:53,220 DEBUG   HandlerThread:367487 [handler.py:handle_request():146] handle_request: status_report
2024-07-24 05:39:58,221 DEBUG   HandlerThread:367487 [handler.py:handle_request():146] handle_request: status_report
2024-07-24 05:40:03,222 DEBUG   HandlerThread:367487 [handler.py:handle_request():146] handle_request: status_report
2024-07-24 05:40:08,223 DEBUG   HandlerThread:367487 [handler.py:handle_request():146] handle_request: status_report
